Workbook

Sheet 객실배치
B1: 춘계 전국 목회자 친교회 객실 배정
B2: 친교회 | C2: 입실자 | D2: 인원 | E2: 동 | F2: 평 | G2: 호실 | H2: 기간 | I2: 열쇠 반납 | J2: 3박 | K2: 친교회코드
B3: 서울친교회 | C3: 김경석, 채승희 | D3: 2 | E3: 본관 | F3: 17 | G3: 1218 | H3: 2 | K3: 1
B4: 서울친교회 | C4: 김관준, 오상률, 박세호, 이강헌 | D4: 4 | E4: 별관 | F4: 25 | G4: 2104 | H4: 2 | K4: 1
B5: 서울친교회 | C5: 김명순 부부, 최정기 | D5: 3 | E5: 본관 | F5: 25 | G5: 1203 | H5: 3 | J5: 19 | K5: 1
B6: 서울친교회 | C6: 김상완, 김성혜 | D6: 2 | E6: 본관 | F6: 17 | G6: 1205 | H6: 1 | K6: 1
B7: 서울친교회 | C7: 김성진, 이승호 정창욱, 김지수 | D7: 4 | E7: 별관 | F7: 25 | G7: 2103 | H7: 2 | K7: 1
B8: 서울친교회 | C8: 김학수, 주견자 | D8: 2 | E8: 본관 | F8: 17 | G8: 1209 | H8: 2 | K8: 1
B9: 서울친교회 | C9: 김홍길, 이순자 | D9: 2 | E9: 본관 | F9: 17 | G9: 1201 | H9: 2 | K9: 1
B10: 서울친교회 | C10: 라영규, 장윤숙 | D10: 2 | E10: 본관 | F10: 17 | G10: 1202 | H10: 2 | K10: 1
B11: 서울친교회 | C11: 박세용 부부, 김병석 부부 | D11: 4 | E11: 본관 | F11: 25 | G11: 1208 | H11: 1 | K11: 1
B12: 서울친교회 | C12: 송기창 가족 | D12: 5 | E12: 별관 | F12: 25 | G12: 2109 | H12: 2 | K12: 1
B13: 서울친교회 | C13: 심재혁, 엄승희 | D13: 2 | E13: 별관 | F13: 17 | G13: 2102 | H13: 2 | K13: 1
B14: 서울친교회 | C14: 유병현 가족 | D14: 4 | E14: 별관 | F14: 17 | G14: 2106 | H14: 3 | J14: 19 | K14: 1
B15: 서울친교회 | C15: 이명규, 남선희 | D15: 2 | E15: 본관 | F15: 17 | G15: 1211 | H15: 2 | K15: 1
B16: 서울친교회 | C16: 이선정 가족 | D16: 5 | E16: 별관 | F16: 25 | G16: 2507 | H16: 1 | K16: 1
B17: 서울친교회 | C17: 이승록, 손은미 | D17: 2 | E17: 별관 | F17: 17 | G17: 2101 | H17: 3 | J17: 19 | K17: 1
B18: 서울친교회 | C18: 이승훈 가족 | D18: 4 | E18: 별관 | F18: 17 | G18: 2105 | H18: 3 | J18: 19 | K18: 1
B19: 서울친교회 | C19: 이은철, 임현희 | D19: 2 | E19: 본관 | F19: 17 | G19: 1214 | H19: 2 | K19: 1
B20: 서울친교회 | C20: 이정삼, 김용숙 | D20: 2 | E20: 본관 | F20: 17 | G20: 1206 | H20: 3 | J20: 19 | K20: 1
B21: 서울친교회 | C21: 이종호 이미선 | D21: 2 | E21: 별관 | F21: 17 | G21: 2602 | H21: 2 | K21: 1
B22: 서울친교회 | C22: 이형주 가족 | D22: 5 | E22: 별관 | F22: 25 | G22: 2108 | H22: 2 | K22: 1
B23: 서울친교회 | C23: 장창호, 정해숙 | D23: 2 | E23: 본관 | F23: 17 | G23: 1215 | H23: 2 | K23: 1
B24: 서울친교회 | C24: 최정식, 권미애 | D24: 2 | E24: 본관 | F24: 17 | G24: 1210 | H24: 2 | K24: 1
B25: 경인친교회 | C25: 강태진, 김종주, 자녀 1 | D25: 3 | E25: 별관 | F25: 25 | G25: 2203 | H25: 2 | K25: 2
B26: 경인친교회 | C26: 김기명, 김미희 | D26: 2 | E26: 별관 | F26: 17 | G26: 2208 | H26: 2 | K26: 2
B27: 경인친교회 | C27: 김용웅, 박옥자 | D27: 2 | E27: 본관 | F27: 17 | G27: 1309 | H27: 2 | K27: 2
B28: 경인친교회 | C28: 김조동, SWATH, SREY AUN | D28: 3 | E28: 본관 | F28: 25 | G28: 1608 | H28: 3 | J28: 22 | K28: 2
B29: 경인친교회 | C29: 문정용, 김미영 | D29: 2 | E29: 별관 | F29: 17 | G29: 2501 | H29: 2 | K29: 2
B30: 경인친교회 | C30: 박동근, 석복순 | D30: 2 | E30: 별관 | F30: 17 | G30: 2206 | H30: 2 | K30: 2
B31: 경인친교회 | C31: 박선종, 윤순자 | D31: 2 | E31: 본관 | F31: 17 | G31: 1301 | H31: 2 | K31: 2
B32: 경인친교회 | C32: 박일래, 하은주, 김영태, 이지은 | D32: 4 | E32: 본관 | F32: 25 | G32: 1216 | H32: 2 | K32: 2
B33: 경인친교회 | C33: 박창신, 장혜경 | D33: 2 | E33: 본관 | F33: 25 | G33: 1412 | H33: 3 | J33: 19 | K33: 2
B34: 경인친교회 | C34: 손인석, 성정희 | D34: 2 | E34: 별관 | F34: 17 | G34: 2107 | H34: 2 | K34: 2
B35: 경인친교회 | C35: 신철남 김만홍 | D35: 2 | E35: 본관 | F35: 25 | G35: 1511 | H35: 2 | K35: 2
B36: 경인친교회 | C36: 여우석, 강미선 | D36: 2 | E36: 별관 | F36: 17 | G36: 2207 | H36: 2 | K36: 2
B37: 경인친교회 | C37: 유병선, 신효선 가족 | D37: 4 | E37: 별관 | F37: 25 | G37: 2204 | H37: 2 | K37: 2
B38: 경인친교회 | C38: 유재명, 신경애 | D38: 2 | E38: 별관 | F38: 17 | G38: 2202 | H38: 2 | K38: 2
B39: 경인친교회 | C39: 윤석호, 유영이, 엄선용, 허성구 | D39: 4 | E39: 본관 | F39: 25 | G39: 1212 | H39: 2 | K39: 2
B40: 경인친교회 | C40: 이상돈, 김 선 | D40: 2 | E40: 별관 | F40: 17 | G40: 2201 | H40: 2 | K40: 2
...

Sheet 통계
B1: 친교회 및 기관별 객실 현황 | J1: 객실 비용 | O1: 3박 객실
O2: 19일 ~ 22일 | P2: 20일 ~ 23일
B3: 친교회 | C3: 전체인원 | D3: 17평 | E3: 25평 | F3: 1박 | G3: 2박 | H3: 3박 | J3: 객실 구분 | K3: 수량 | L3: 소계 | O3: {=_xlfn._xlws.FILTER(객실배치!G:G, (객실배치!J:J=19))} -> 1203 | P3: {=_xlfn._xlws.FILTER(객실배치!G:G, (객실배치!J:J=22))} -> 1608
B4: 서울친교회 | C4: =SUMIF(객실배치!B:B, 통계!B4, 객실배치!D:D) -> 64 | D4: =COUNTIFS(객실배치!B:B, 통계!B4, 객실배치!F:F, 17) -> 15 | E4: =COUNTIFS(객실배치!B:B, 통계!B4, 객실배치!F:F, 25) -> 7 | F4: =COUNTIFS(객실배치!B:B, 통계!B4, 객실배치!H:H, 1) -> 3 | G4: =COUNTIFS(객실배치!B:B, 통계!B4, 객실배치!H:H, 2) -> 14 | H4: =COUNTIFS(객실배치!B:B, 통계!B4, 객실배치!H:H, 3) -> 5 | J4: 17평 1박 | K4: =COUNTIFS(객실배치!F:F,17,객실배치!H:H,1) -> 1 | L4: =SUM(K4*70000) -> 70000 | M4: =SUM(L4:L6) -> 9940000 | O4: 2106 | P4: 1609
B5: 경인친교회 | C5: =SUMIF(객실배치!B:B, 통계!B5, 객실배치!D:D) -> 65 | D5: =COUNTIFS(객실배치!B:B, 통계!B5, 객실배치!F:F, 17) -> 12 | E5: =COUNTIFS(객실배치!B:B, 통계!B5, 객실배치!F:F, 25) -> 12 | F5: =COUNTIFS(객실배치!B:B, 통계!B5, 객실배치!H:H, 1) -> 0 | G5: =COUNTIFS(객실배치!B:B, 통계!B5, 객실배치!H:H, 2) -> 21 | H5: =COUNTIFS(객실배치!B:B, 통계!B5, 객실배치!H:H, 3) -> 3 | J5: 17평 2박 | K5: =COUNTIFS(객실배치!F:F,17,객실배치!H:H,2) -> 60 | L5: =SUM(K5*70000*2) -> 8400000 | O5: 2101
B6: 경원친교회 | C6: =SUMIF(객실배치!B:B, 통계!B6, 객실배치!D:D) -> 57 | D6: =COUNTIFS(객실배치!B:B, 통계!B6, 객실배치!F:F, 17) -> 13 | E6: =COUNTIFS(객실배치!B:B, 통계!B6, 객실배치!F:F, 25) -> 7 | F6: =COUNTIFS(객실배치!B:B, 통계!B6, 객실배치!H:H, 1) -> 0 | G6: =COUNTIFS(객실배치!B:B, 통계!B6, 객실배치!H:H, 2) -> 18 | H6: =COUNTIFS(객실배치!B:B, 통계!B6, 객실배치!H:H, 3) -> 2 | J6: 17평 3박 | K6: =COUNTIFS(객실배치!F:F,17,객실배치!H:H,3) -> 7 | L6: =SUM(K6*70000*3) -> 1470000 | O6: 2105
B7: 경충친교회 | C7: =SUMIF(객실배치!B:B, 통계!B7, 객실배치!D:D) -> 41 | D7: =COUNTIFS(객실배치!B:B, 통계!B7, 객실배치!F:F, 17) -> 9 | E7: =COUNTIFS(객실배치!B:B, 통계!B7, 객실배치!F:F, 25) -> 6 | F7: =COUNTIFS(객실배치!B:B, 통계!B7, 객실배치!H:H, 1) -> 0 | G7: =COUNTIFS(객실배치!B:B, 통계!B7, 객실배치!H:H, 2) -> 14 | H7: =COUNTIFS(객실배치!B:B, 통계!B7, 객실배치!H:H, 3) -> 1 | J7: 25평 1박 | K7: =COUNTIFS(객실배치!F:F,25,객실배치!H:H,1) -> 3 | L7: =SUM(K7*90000) -> 270000 | M7: =SUM(L7:L9) -> 8370000 | O7: 1206
B8: 중부친교회 | C8: =SUMIF(객실배치!B:B, 통계!B8, 객실배치!D:D) -> 27 | D8: =COUNTIFS(객실배치!B:B, 통계!B8, 객실배치!F:F, 17) -> 5 | E8: =COUNTIFS(객실배치!B:B, 통계!B8, 객실배치!F:F, 25) -> 3 | F8: =COUNTIFS(객실배치!B:B, 통계!B8, 객실배치!H:H, 1) -> 0 | G8: =COUNTIFS(객실배치!B:B, 통계!B8, 객실배치!H:H, 2) -> 8 | H8: =COUNTIFS(객실배치!B:B, 통계!B8, 객실배치!H:H, 3) -> 0 | J8: 25평 2박 | K8: =COUNTIFS(객실배치!F:F,25,객실배치!H:H,2) -> 36 | L8: =SUM(K8*90000*2) -> 6480000 | O8: 1412
B9: 호남친교회 | C9: =SUMIF(객실배치!B:B, 통계!B9, 객실배치!D:D) -> 12 | D9: =COUNTIFS(객실배치!B:B, 통계!B9, 객실배치!F:F, 17) -> 2 | E9: =COUNTIFS(객실배치!B:B, 통계!B9, 객실배치!F:F, 25) -> 2 | F9: =COUNTIFS(객실배치!B:B, 통계!B9, 객실배치!H:H, 1) -> 0 | G9: =COUNTIFS(객실배치!B:B, 통계!B9, 객실배치!H:H, 2) -> 4 | H9: =COUNTIFS(객실배치!B:B, 통계!B9, 객실배치!H:H, 3) -> 0 | J9: 25평 3박 | K9: =COUNTIFS(객실배치!F:F,25,객실배치!H:H,3) -> 6 | L9: =SUM(K9*90000*3) -> 1620000 | O9: 1409
B10: 영남친교회 | C10: =SUMIF(객실배치!B:B, 통계!B10, 객실배치!D:D) -> 33 | D10: =COUNTIFS(객실배치!B:B, 통계!B10, 객실배치!F:F, 17) -> 7 | E10: =COUNTIFS(객실배치!B:B, 통계!B10, 객실배치!F:F, 25) -> 5 | F10: =COUNTIFS(객실배치!B:B, 통계!B10, 객실배치!H:H, 1) -> 1 | G10: =COUNTIFS(객실배치!B:B, 통계!B10, 객실배치!H:H, 2) -> 10 | H10: =COUNTIFS(객실배치!B:B, 통계!B10, 객실배치!H:H, 3) -> 1 | O10: 1312
B11: 신학교 | C11: =SUMIF(객실배치!B:B, 통계!B11, 객실배치!D:D) -> 19 | D11: =COUNTIFS(객실배치!B:B, 통계!B11, 객실배치!F:F, 17) -> 5 | E11: =COUNTIFS(객실배치!B:B, 통계!B11, 객실배치!F:F, 25) -> 3 | F11: =COUNTIFS(객실배치!B:B, 통계!B11, 객실배치!H:H, 1) -> 0 | G11: =COUNTIFS(객실배치!B:B, 통계!B11, 객실배치!H:H, 2) -> 7 | H11: =COUNTIFS(객실배치!B:B, 통계!B11, 객실배치!H:H, 3) -> 1 | J11: 합계 | K11: =SUM(M4,M7) -> 18310000 | O11: 1305
B12: 합계 | C12: =SUM(C4:C11) -> 318 | D12: =SUM(D4:D11) -> 68 | E12: =SUM(E4:E11) -> 45 | F12: =SUM(F4:F11) -> 4 | G12: =SUM(G4:G11) -> 96 | H12: =SUM(H4:H11) -> 13 | O12: 1302
O13: 1504
B14: 공실 | C14: =SUMIF(객실배치!B:B, 통계!B14, 객실배치!D:D) -> 0 | D14: =COUNTIFS(객실배치!B:B, 통계!B14, 객실배치!F:F, 17) -> 0 | E14: =COUNTIFS(객실배치!B:B, 통계!B14, 객실배치!F:F, 25) -> 2 | F14: =COUNTIFS(객실배치!B:B, 통계!B14, 객실배치!H:H, 1) -> 0 | G14: =COUNTIFS(객실배치!B:B, 통계!B14, 객실배치!H:H, 2) -> 0 | H14: =COUNTIFS(객실배치!B:B, 통계!B14, 객실배치!H:H, 3) -> 0
J15: 침구류 추가 | L15: 1박 객실
B16: 식사 인원 | J16: {=_xlfn._xlws.FILTER(객실배치!G:G, (객실배치!F:F=17)*(객실배치!D:D>=4))} -> 2106 | L16: {=_xlfn._xlws.FILTER(객실배치!G:G, (객실배치!H:H=1))} -> 1205
J17: 2105 | L17: 1208
C18: 월요일 | E18: 화요일 | G18: 수요일 | J18: 2305 | L18: 2507
B19: 아침 | E19: 230 | G19: 200 | J19: 2306 | L19: 1307
B20: 점심 | G20: 250 | J20: 2307
B21: 저녁 | C21: 270 | E21: 280 | J21: 2405
B22: 소계 | C22: =SUM(C19:C21) -> 270 | E22: =SUM(E19:E21) -> 510 | G22: =SUM(G19:G21) -> 450 | J22: 2505
J23: 2406
B24: 예상비용 | C24: =SUM(C22:G22) -> 1230 | D24: 명 | E24: =SUM(C24*11000) -> 13530000 | J24: 2407
J25: 2601
B26: 화요일 중식비 | C26: 3150000
B29: 성호 리조트 지불액 | D29: =SUM(K11,E24) -> 31840000

Sheet 리조트보고용
B2: 객실 예약 현황
B3: 친교회 | C3: 17평 | D3: 25평 | E3: 1박 | F3: 2박 | G3: 3박
B4: 서울친교회 | C4: 15 | D4: 7 | E4: 3 | F4: 14 | G4: 5
B5: 경인친교회 | C5: 12 | D5: 12 | E5: 0 | F5: 21 | G5: 3
B6: 경원친교회 | C6: 13 | D6: 7 | E6: 0 | F6: 18 | G6: 2
B7: 경충친교회 | C7: 9 | D7: 6 | E7: 0 | F7: 14 | G7: 1
B8: 중부친교회 | C8: 5 | D8: 3 | E8: 0 | F8: 8 | G8: 0
B9: 호남친교회 | C9: 2 | D9: 2 | E9: 0 | F9: 4 | G9: 0
B10: 영남친교회 | C10: 8 | D10: 4 | E10: 1 | F10: 10 | G10: 1
B11: 신학교 | C11: 4 | D11: 3 | E11: 0 | F11: 6 | G11: 1
B12: 합계 | C12: 68 | D12: 44 | E12: 4 | F12: 95 | G12: 13
B15: 엑스트라 객실 | E15: 1박 객실 | F15: 3박 객실
B16: 본관 | C16: 25 | D16: 1307 | F16: 19일 ~ 22일 | G16: 20일 ~ 23일
B17: 본관 | C17: 25 | D17: 1304 | E17: 1205 | F17: 1203 | G17: 1608
B18: 본관 | C18: 25 | D18: 1308 | E18: 1208 | F18: 2106 | G18: 1609
E19: 2507 | F19: 2101
E20: 2205 | F20: 2105
B21: 객실 구분 | C21: 수량 | F21: 1206
B22: 17평 1박 | C22: 2 | F22: 1412
B23: 17평 2박 | C23: 59 | F23: 1409
B24: 17평 3박 | C24: 7 | F24: 1312
B25: 25평 1박 | C25: 2 | F25: 1305
B26: 25평 2박 | C26: 36 | F26: 1302
B27: 25평 3박 | C27: 6 | F27: 1504
B29: 식사 인원
C30: 월요일 | E30: 화요일 | G30: 수요일
B31: 아침 | E31: 230 | G31: 200
B32: 점심 | G32: 250
B33: 저녁 | C33: 270 | E33: 280
B34: 소계 | C34: 270 | E34: 510 | G34: 450
